function c() {
	b();
}

function b() {
	a();
}

function a() {
	try {
	setTimeout(function() {
		throw new Error('se ha producido error');
    },10);
    } catch (e) { 
    	console.log("se ha capturado una excepci√≥n");
    }
}

c();
